{
	"vulinfoid": "JVNDB-2019-012689",
	"vulinfodata": {
		"title": "typed_ast における境界外読み取りに関する脆弱性",
		"vulinfodescription": {
			"overview": "typed_ast には、境界外読み取りに関する脆弱性が存在します。"
		},
		"affected": {
			"affecteditem": [
				{
					"name": "Python Software Foundation",
					"productname": "typed_ast",
					"cpe": {
						"text": "cpe:/a:python:typed_ast",
						"version": "2.2"
					},
					"versionnumber": [
						"1.3.0",
						"1.3.1"
					]
				}
			]
		},
		"impact": {
			"cvss": [
				{
					"version": "2.0",
					"severity": {
						"text": "Medium",
						"type": "Base"
					},
					"base": "5",
					"vector": "AV:N/AC:L/Au:N/C:N/I:N/A:P"
				},
				{
					"version": "3.0",
					"severity": {
						"text": "High",
						"type": "Base"
					},
					"base": "7.5",
					"vector": "CVSS:3.0/AV:N/AC:L/PR:N/UI:N/S:U/C:N/I:N/A:H"
				}
			],
			"impactitem": {
				"description": "サービス運用妨害 (DoS) 状態にされる可能性があります。"
			}
		},
		"solution": {
			"solutionitem": {
				"description": "ベンダより正式な対策が公開されています。ベンダ情報を参照して適切な対策を実施してください。"
			}
		},
		"related": {
			"relateditem": [
				{
					"type": "vendor",
					"name": "GitHub",
					"vulinfoid": "bpo-35766: Merge typed_ast back into CPython (GH-11645)",
					"url": "https://github.com/python/cpython/commit/dcfcd146f8e6fc5c2fc16a4c192a0c5f5ca8c53c"
				},
				{
					"type": "vendor",
					"name": "GitHub",
					"vulinfoid": "Fully incorporate the code from Python 3.7.2 (#78)",
					"url": "https://github.com/python/typed_ast/commit/156afcb26c198e162504a57caddfe0acd9ed7dce"
				},
				{
					"type": "vendor",
					"name": "GitHub",
					"vulinfoid": "Fix two out-of-bounds array reads (#99)",
					"url": "https://github.com/python/typed_ast/commit/dc317ac9cff859aa84eeabe03fb5004982545b3b"
				},
				{
					"type": "vendor",
					"name": "GitHub",
					"vulinfoid": "bpo-36495: Fix two out-of-bounds array reads (GH-12641)",
					"url": "https://github.com/python/cpython/commit/a4d78362397fc3bced6ea80fbc7b5f4827aec55e"
				},
				{
					"type": "vendor",
					"name": "Python bug tracker",
					"vulinfoid": "issue36495",
					"url": "https://bugs.python.org/issue36495"
				},
				{
					"type": "advisory",
					"name": "Common Vulnerabilities and Exposures (CVE)",
					"vulinfoid": "CVE-2019-19274",
					"url": "https://cve.mitre.org/cgi-bin/cvename.cgi?name=CVE-2019-19274"
				},
				{
					"type": "advisory",
					"name": "National Vulnerability Database (NVD)",
					"vulinfoid": "CVE-2019-19274",
					"url": "https://nvd.nist.gov/vuln/detail/CVE-2019-19274"
				},
				{
					"type": "cwe",
					"name": "JVNDB",
					"vulinfoid": "CWE-125",
					"url": "https://cwe.mitre.org/data/definitions/125.html",
					"title": "境界外読み取り"
				}
			]
		},
		"history": {
			"historyitem": [
				{
					"historyno": "1",
					"datetime": "2019-12-11T10:43:26+09:00",
					"description": "[2019年12月11日]\\n  掲載"
				}
			]
		},
		"datefirstpublished": "2019-12-11T10:43:26+09:00",
		"datelastupdated": "2019-12-11T10:43:26+09:00",
		"datepublic": "2019-03-31T00:00:00+09:00"
	}
}
