{
  "vulinfoid": "JVNDB-2022-020663",
  "vulinfodata": {
    "title": "Python Software Foundation の Python Pillow における脆弱性",
    "vulinfodescription": {
      "overview": "Python Software Foundation の Python Pillow には、不特定の脆弱性が存在します。"
    },
    "affected": {
      "affecteditem": [
        {
          "name": "Python Software Foundation",
          "productname": "Python Pillow",
          "cpe": {
            "text": "cpe:/a:python:pillow",
            "version": "2.2"
          },
          "versionnumber": [
            "9.2.0 未満"
          ]
        }
      ]
    },
    "impact": {
      "cvss": [
        {
          "version": "3.0",
          "severity": {
            "text": "High",
            "type": "Base"
          },
          "base": "7.5",
          "vector": "CVSS:3.0/AV:N/AC:L/PR:N/UI:N/S:U/C:N/I:N/A:H"
        }
      ],
      "impactitem": {
        "description": "サービス運用妨害 (DoS) 状態にされる可能性があります。"
      }
    },
    "solution": {
      "solutionitem": {
        "description": "ベンダアドバイザリまたはパッチ情報が公開されています。参考情報を参照して適切な対策を実施してください。"
      }
    },
    "related": {
      "relateditem": [
        {
          "type": "advisory",
          "name": "Common Vulnerabilities and Exposures (CVE)",
          "vulinfoid": "CVE-2022-45198",
          "url": "https://www.cve.org/CVERecord?id=CVE-2022-45198"
        },
        {
          "type": "advisory",
          "name": "National Vulnerability Database (NVD)",
          "vulinfoid": "CVE-2022-45198",
          "url": "https://nvd.nist.gov/vuln/detail/CVE-2022-45198"
        },
        {
          "type": "advisory",
          "name": "関連文書",
          "vulinfoid": "github.com (pull/6402)",
          "url": "https://github.com/python-pillow/Pillow/pull/6402"
        },
        {
          "type": "advisory",
          "name": "関連文書",
          "vulinfoid": "github.com (9.2.0)",
          "url": "https://github.com/python-pillow/Pillow/releases/tag/9.2.0"
        },
        {
          "type": "advisory",
          "name": "関連文書",
          "vulinfoid": "security.gentoo.org (202211-10)",
          "url": "https://security.gentoo.org/glsa/202211-10"
        },
        {
          "type": "advisory",
          "name": "関連文書",
          "vulinfoid": "bugs.gentoo.org (855683)",
          "url": "https://bugs.gentoo.org/855683"
        },
        {
          "type": "advisory",
          "name": "関連文書",
          "vulinfoid": "cwe.mitre.org (409)",
          "url": "https://cwe.mitre.org/data/definitions/409.html"
        },
        {
          "type": "advisory",
          "name": "関連文書",
          "vulinfoid": "github.com (11918eac0628ec8ac0812670d9838361ead2d6a4)",
          "url": "https://github.com/python-pillow/Pillow/commit/11918eac0628ec8ac0812670d9838361ead2d6a4"
        },
        {
          "type": "cwe",
          "name": "JVNDB",
          "vulinfoid": "CWE-Other",
          "url": "https://www.ipa.go.jp/security/vuln/scap/cwe.html",
          "title": "その他"
        }
      ]
    },
    "history": {
      "historyitem": [
        {
          "historyno": "1",
          "datetime": "2023-11-06T17:06:01+09:00",
          "description": "[2023年11月06日]\\n  掲載"
        }
      ]
    },
    "datefirstpublished": "2023-11-06T17:06:01+09:00",
    "datelastupdated": "2023-11-06T17:06:01+09:00",
    "datepublic": "2022-11-14T00:00:00+09:00"
  }
}
